Workbook

Sheet FORMULA.DATASET
A1: id_incidencia | B1: fecha_reporte | C1: mes | D1: hora_reporte | E1: estacion | F1: linea | G1: tipo_equipo | H1: tipo_incidencia | I1: prioridad | J1: estado | K1: fecha_atencion | L1: tiempo_atencion_horas | M1: area_responsable
A2: =ROW()-1 -> 1 | B2: =DATE(2023,1,1)+RANDBETWEEN(0,730) -> 45259 | C2: =TEXT(B2,"yyyy-mm") -> 2023-11 | D2: =RANDBETWEEN(0,23)/24 + RANDBETWEEN(0,59)/1440 -> 0.37361111 | E2: {=INDEX(lista!$A$1:$A$12, RANDBETWEEN(1, 12))} -> Ayacucho | F2: Línea 1 | G2: {=INDEX(lista!$B$1:$B$6, RANDBETWEEN(1, 6))} -> MET | H2: {=INDEX(lista!$C$1:$C$4, RANDBETWEEN(1, 4))} -> Daño en infraestructura | I2: =CHOOSE(RANDBETWEEN(1,10),"Baja","Baja","Baja","Media","Media","Media","Media","Alta","Alta","Alta") -> Baja | J2: =CHOOSE(RANDBETWEEN(1,10),"Atendida","Atendida","Atendida","En curso","En curso","Pendiente","Pendiente","Atendida","Atendida","Atendida") -> Atendida | K2: =IF(J2="Atendida",B2+RANDBETWEEN(0,2),"") -> 45261 | L2: =IF(J2="Atendida",RANDBETWEEN(1,24),"") -> 19 | M2: =IF(OR(G2="Escalera eléctrica",G2="Ascensor",G2="Puertas de andén"),"Mantenimiento",IF(G2="Sistema eléctrico","Infraestructura","Telecomunicaciones")) -> Telecomunicaciones
A3: =ROW()-1 -> 2 | B3: =DATE(2023,1,1)+RANDBETWEEN(0,730) -> 45166 | C3: =TEXT(B3,"yyyy-mm") -> 2023-08 | D3: =RANDBETWEEN(0,23)/24 + RANDBETWEEN(0,59)/1440 -> 0.53125 | E3: {=INDEX(lista!$A$1:$A$12, RANDBETWEEN(1, 12))} -> Atocongo | F3: Línea 1 | G3: {=INDEX(lista!$B$1:$B$6, RANDBETWEEN(1, 6))} -> Radio | H3: {=INDEX(lista!$C$1:$C$4, RANDBETWEEN(1, 4))} -> Falla eléctrica | I3: =CHOOSE(RANDBETWEEN(1,10),"Baja","Baja","Baja","Media","Media","Media","Media","Alta","Alta","Alta") -> Media | J3: =CHOOSE(RANDBETWEEN(1,10),"Atendida","Atendida","Atendida","En curso","En curso","Pendiente","Pendiente","Atendida","Atendida","Atendida") -> Atendida | K3: =IF(J3="Atendida",B3+RANDBETWEEN(0,2),"") -> 45168 | L3: =IF(J3="Atendida",RANDBETWEEN(1,24),"") -> 13 | M3: =IF(OR(G3="Escalera eléctrica",G3="Ascensor",G3="Puertas de andén"),"Mantenimiento",IF(G3="Sistema eléctrico","Infraestructura","Telecomunicaciones")) -> Telecomunicaciones
A4: =ROW()-1 -> 3 | B4: =DATE(2023,1,1)+RANDBETWEEN(0,730) -> 45286 | C4: =TEXT(B4,"yyyy-mm") -> 2023-12 | D4: =RANDBETWEEN(0,23)/24 + RANDBETWEEN(0,59)/1440 -> 0.85833333 | E4: {=INDEX(lista!$A$1:$A$12, RANDBETWEEN(1, 12))} -> Gamarra | F4: Línea 1 | G4: {=INDEX(lista!$B$1:$B$6, RANDBETWEEN(1, 6))} -> MET | H4: {=INDEX(lista!$C$1:$C$4, RANDBETWEEN(1, 4))} -> Mantenimiento preventivo | I4: =CHOOSE(RANDBETWEEN(1,10),"Baja","Baja","Baja","Media","Media","Media","Media","Alta","Alta","Alta") -> Baja | J4: =CHOOSE(RANDBETWEEN(1,10),"Atendida","Atendida","Atendida","En curso","En curso","Pendiente","Pendiente","Atendida","Atendida","Atendida") -> Atendida | K4: =IF(J4="Atendida",B4+RANDBETWEEN(0,2),"") -> 45287 | L4: =IF(J4="Atendida",RANDBETWEEN(1,24),"") -> 9 | M4: =IF(OR(G4="Escalera eléctrica",G4="Ascensor",G4="Puertas de andén"),"Mantenimiento",IF(G4="Sistema eléctrico","Infraestructura","Telecomunicaciones")) -> Telecomunicaciones
A5: =ROW()-1 -> 4 | B5: =DATE(2023,1,1)+RANDBETWEEN(0,730) -> 45426 | C5: =TEXT(B5,"yyyy-mm") -> 2024-05 | D5: =RANDBETWEEN(0,23)/24 + RANDBETWEEN(0,59)/1440 -> 0.71388889 | E5: {=INDEX(lista!$A$1:$A$12, RANDBETWEEN(1, 12))} -> Bayóvar | F5: Línea 1 | G5: {=INDEX(lista!$B$1:$B$6, RANDBETWEEN(1, 6))} -> Radio | H5: {=INDEX(lista!$C$1:$C$4, RANDBETWEEN(1, 4))} -> Mantenimiento preventivo | I5: =CHOOSE(RANDBETWEEN(1,10),"Baja","Baja","Baja","Media","Media","Media","Media","Alta","Alta","Alta") -> Media | J5: =CHOOSE(RANDBETWEEN(1,10),"Atendida","Atendida","Atendida","En curso","En curso","Pendiente","Pendiente","Atendida","Atendida","Atendida") -> Atendida | K5: =IF(J5="Atendida",B5+RANDBETWEEN(0,2),"") -> 45426 | L5: =IF(J5="Atendida",RANDBETWEEN(1,24),"") -> 22 | M5: =IF(OR(G5="Escalera eléctrica",G5="Ascensor",G5="Puertas de andén"),"Mantenimiento",IF(G5="Sistema eléctrico","Infraestructura","Telecomunicaciones")) -> Telecomunicaciones
A6: =ROW()-1 -> 5 | B6: =DATE(2023,1,1)+RANDBETWEEN(0,730) -> 45595 | C6: =TEXT(B6,"yyyy-mm") -> 2024-10 | D6: =RANDBETWEEN(0,23)/24 + RANDBETWEEN(0,59)/1440 -> 0.90208333 | E6: {=INDEX(lista!$A$1:$A$12, RANDBETWEEN(1, 12))} -> Atocongo | F6: Línea 1 | G6: {=INDEX(lista!$B$1:$B$6, RANDBETWEEN(1, 6))} -> Ascensor | H6: {=INDEX(lista!$C$1:$C$4, RANDBETWEEN(1, 4))} -> Falla mecánica | I6: =CHOOSE(RANDBETWEEN(1,10),"Baja","Baja","Baja","Media","Media","Media","Media","Alta","Alta","Alta") -> Baja | J6: =CHOOSE(RANDBETWEEN(1,10),"Atendida","Atendida","Atendida","En curso","En curso","Pendiente","Pendiente","Atendida","Atendida","Atendida") -> Pendiente | K6: =IF(J6="Atendida",B6+RANDBETWEEN(0,2),"") | L6: =IF(J6="Atendida",RANDBETWEEN(1,24),"") | M6: =IF(OR(G6="Escalera eléctrica",G6="Ascensor",G6="Puertas de andén"),"Mantenimiento",IF(G6="Sistema eléctrico","Infraestructura","Telecomunicaciones")) -> Mantenimiento
A7: =ROW()-1 -> 6 | B7: =DATE(2023,1,1)+RANDBETWEEN(0,730) -> 45214 | C7: =TEXT(B7,"yyyy-mm") -> 2023-10 | D7: =RANDBETWEEN(0,23)/24 + RANDBETWEEN(0,59)/1440 -> 0.084722222 | E7: {=INDEX(lista!$A$1:$A$12, RANDBETWEEN(1, 12))} -> Gamarra | F7: Línea 1 | G7: {=INDEX(lista!$B$1:$B$6, RANDBETWEEN(1, 6))} -> TVM | H7: {=INDEX(lista!$C$1:$C$4, RANDBETWEEN(1, 4))} -> Falla mecánica | I7: =CHOOSE(RANDBETWEEN(1,10),"Baja","Baja","Baja","Media","Media","Media","Media","Alta","Alta","Alta") -> Media | J7: =CHOOSE(RANDBETWEEN(1,10),"Atendida","Atendida","Atendida","En curso","En curso","Pendiente","Pendiente","Atendida","Atendida","Atendida") -> Atendida | K7: =IF(J7="Atendida",B7+RANDBETWEEN(0,2),"") -> 45216 | L7: =IF(J7="Atendida",RANDBETWEEN(1,24),"") -> 24 | M7: =IF(OR(G7="Escalera eléctrica",G7="Ascensor",G7="Puertas de andén"),"Mantenimiento",IF(G7="Sistema eléctrico","Infraestructura","Telecomunicaciones")) -> Telecomunicaciones
A8: =ROW()-1 -> 7 | B8: =DATE(2023,1,1)+RANDBETWEEN(0,730) -> 45369 | C8: =TEXT(B8,"yyyy-mm") -> 2024-03 | D8: =RANDBETWEEN(0,23)/24 + RANDBETWEEN(0,59)/1440 -> 0.60694444 | E8: {=INDEX(lista!$A$1:$A$12, RANDBETWEEN(1, 12))} -> Bayóvar | F8: Línea 1 | G8: {=INDEX(lista!$B$1:$B$6, RANDBETWEEN(1, 6))} -> MET | H8: {=INDEX(lista!$C$1:$C$4, RANDBETWEEN(1, 4))} -> Mantenimiento preventivo | I8: =CHOOSE(RANDBETWEEN(1,10),"Baja","Baja","Baja","Media","Media","Media","Media","Alta","Alta","Alta") -> Alta | J8: =CHOOSE(RANDBETWEEN(1,10),"Atendida","Atendida","Atendida","En curso","En curso","Pendiente","Pendiente","Atendida","Atendida","Atendida") -> Atendida | K8: =IF(J8="Atendida",B8+RANDBETWEEN(0,2),"") -> 45370 | L8: =IF(J8="Atendida",RANDBETWEEN(1,24),"") -> 24 | M8: =IF(OR(G8="Escalera eléctrica",G8="Ascensor",G8="Puertas de andén"),"Mantenimiento",IF(G8="Sistema eléctrico","Infraestructura","Telecomunicaciones")) -> Telecomunicaciones
A9: =ROW()-1 -> 8 | B9: =DATE(2023,1,1)+RANDBETWEEN(0,730) -> 45631 | C9: =TEXT(B9,"yyyy-mm") -> 2024-12 | D9: =RANDBETWEEN(0,23)/24 + RANDBETWEEN(0,59)/1440 -> 0.26458333 | E9: {=INDEX(lista!$A$1:$A$12, RANDBETWEEN(1, 12))} -> Bayóvar | F9: Línea 1 | G9: {=INDEX(lista!$B$1:$B$6, RANDBETWEEN(1, 6))} -> Torniquete | H9: {=INDEX(lista!$C$1:$C$4, RANDBETWEEN(1, 4))} -> Mantenimiento preventivo | I9: =CHOOSE(RANDBETWEEN(1,10),"Baja","Baja","Baja","Media","Media","Media","Media","Alta","Alta","Alta") -> Baja | J9: =CHOOSE(RANDBETWEEN(1,10),"Atendida","Atendida","Atendida","En curso","En curso","Pendiente","Pendiente","Atendida","Atendida","Atendida") -> Atendida | K9: =IF(J9="Atendida",B9+RANDBETWEEN(0,2),"") -> 45632 | L9: =IF(J9="Atendida",RANDBETWEEN(1,24),"") -> 13 | M9: =IF(OR(G9="Escalera eléctrica",G9="Ascensor",G9="Puertas de andén"),"Mantenimiento",IF(G9="Sistema eléctrico","Infraestructura","Telecomunicaciones")) -> Telecomunicaciones
A10: =ROW()-1 -> 9 | B10: =DATE(2023,1,1)+RANDBETWEEN(0,730) -> 44928 | C10: =TEXT(B10,"yyyy-mm") -> 2023-01 | D10: =RANDBETWEEN(0,23)/24 + RANDBETWEEN(0,59)/1440 -> 0.098611111 | E10: {=INDEX(lista!$A$1:$A$12, RANDBETWEEN(1, 12))} -> Villa El Salvador | F10: Línea 1 | G10: {=INDEX(lista!$B$1:$B$6, RANDBETWEEN(1, 6))} -> TVM | H10: {=INDEX(lista!$C$1:$C$4, RANDBETWEEN(1, 4))} -> Mantenimiento preventivo | I10: =CHOOSE(RANDBETWEEN(1,10),"Baja","Baja","Baja","Media","Media","Media","Media","Alta","Alta","Alta") -> Baja | J10: =CHOOSE(RANDBETWEEN(1,10),"Atendida","Atendida","Atendida","En curso","En curso","Pendiente","Pendiente","Atendida","Atendida","Atendida") -> Atendida | K10: =IF(J10="Atendida",B10+RANDBETWEEN(0,2),"") -> 44929 | L10: =IF(J10="Atendida",RANDBETWEEN(1,24),"") -> 24 | M10: =IF(OR(G10="Escalera eléctrica",G10="Ascensor",G10="Puertas de andén"),"Mantenimiento",IF(G10="Sistema eléctrico","Infraestructura","Telecomunicaciones")) -> Telecomunicaciones
A11: =ROW()-1 -> 10 | B11: =DATE(2023,1,1)+RANDBETWEEN(0,730) -> 45482 | C11: =TEXT(B11,"yyyy-mm") -> 2024-07 | D11: =RANDBETWEEN(0,23)/24 + RANDBETWEEN(0,59)/1440 -> 0.30069444 | E11: {=INDEX(lista!$A$1:$A$12, RANDBETWEEN(1, 12))} -> Santa Rosa | F11: Línea 1 | G11: {=INDEX(lista!$B$1:$B$6, RANDBETWEEN(1, 6))} -> Torniquete | H11: {=INDEX(lista!$C$1:$C$4, RANDBETWEEN(1, 4))} -> Falla eléctrica | I11: =CHOOSE(RANDBETWEEN(1,10),"Baja","Baja","Baja","Media","Media","Media","Media","Alta","Alta","Alta") -> Media | J11: =CHOOSE(RANDBETWEEN(1,10),"Atendida","Atendida","Atendida","En curso","En curso","Pendiente","Pendiente","Atendida","Atendida","Atendida") -> Pendiente | K11: =IF(J11="Atendida",B11+RANDBETWEEN(0,2),"") | L11: =IF(J11="Atendida",RANDBETWEEN(1,24),"") | M11: =IF(OR(G11="Escalera eléctrica",G11="Ascensor",G11="Puertas de andén"),"Mantenimiento",IF(G11="Sistema eléctrico","Infraestructura","Telecomunicaciones")) -> Telecomunicaciones
A12: =ROW()-1 -> 11 | B12: =DATE(2023,1,1)+RANDBETWEEN(0,730) -> 45420 | C12: =TEXT(B12,"yyyy-mm") -> 2024-05 | D12: =RANDBETWEEN(0,23)/24 + RANDBETWEEN(0,59)/1440 -> 0.33333333 | E12: {=INDEX(lista!$A$1:$A$12, RANDBETWEEN(1, 12))} -> Angamos | F12: Línea 1 | G12: {=INDEX(lista!$B$1:$B$6, RANDBETWEEN(1, 6))} -> Torniquete | H12: {=INDEX(lista!$C$1:$C$4, RANDBETWEEN(1, 4))} -> Falla eléctrica | I12: =CHOOSE(RANDBETWEEN(1,10),"Baja","Baja","Baja","Media","Media","Media","Media","Alta","Alta","Alta") -> Media | J12: =CHOOSE(RANDBETWEEN(1,10),"Atendida","Atendida","Atendida","En curso","En curso","Pendiente","Pendiente","Atendida","Atendida","Atendida") -> Atendida | K12: =IF(J12="Atendida",B12+RANDBETWEEN(0,2),"") -> 45421 | L12: =IF(J12="Atendida",RANDBETWEEN(1,24),"") -> 6 | M12: =IF(OR(G12="Escalera eléctrica",G12="Ascensor",G12="Puertas de andén"),"Mantenimiento",IF(G12="Sistema eléctrico","Infraestructura","Telecomunicaciones")) -> Telecomunicaciones
A13: =ROW()-1 -> 12 | B13: =DATE(2023,1,1)+RANDBETWEEN(0,730) -> 45441 | C13: =TEXT(B13,"yyyy-mm") -> 2024-05 | D13: =RANDBETWEEN(0,23)/24 + RANDBETWEEN(0,59)/1440 -> 0.47708333 | E13: {=INDEX(lista!$A$1:$A$12, RANDBETWEEN(1, 12))} -> Villa El Salvador | F13: Línea 1 | G13: {=INDEX(lista!$B$1:$B$6, RANDBETWEEN(1, 6))} -> Ascensor | H13: {=INDEX(lista!$C$1:$C$4, RANDBETWEEN(1, 4))} -> Falla mecánica | I13: =CHOOSE(RANDBETWEEN(1,10),"Baja","Baja","Baja","Media","Media","Media","Media","Alta","Alta","Alta") -> Baja | J13: =CHOOSE(RANDBETWEEN(1,10),"Atendida","Atendida","Atendida","En curso","En curso","Pendiente","Pendiente","Atendida","Atendida","Atendida") -> Atendida | K13: =IF(J13="Atendida",B13+RANDBETWEEN(0,2),"") -> 45443 | L13: =IF(J13="Atendida",RANDBETWEEN(1,24),"") -> 20 | M13: =IF(OR(G13="Escalera eléctrica",G13="Ascensor",G13="Puertas de andén"),"Mantenimiento",IF(G13="Sistema eléctrico","Infraestructura","Telecomunicaciones")) -> Mantenimiento
... A501: =ROW()-1 -> 500 | B501: =DATE(2023,1,1)+RANDBETWEEN(0,730) -> 45634 | C501: =TEXT(B501,"yyyy-mm") -> 2024-12 | D501: =RANDBETWEEN(0,23)/24 + RANDBETWEEN(0,59)/1440 -> 0.67708333 | E501: {=INDEX(lista!$A$1:$A$12, RANDBETWEEN(1, 12))} -> Pumacahua | F501: Línea 1 | G501: {=INDEX(lista!$B$1:$B$6, RANDBETWEEN(1, 6))} -> Radio | H501: {=INDEX(lista!$C$1:$C$4, RANDBETWEEN(1, 4))} -> Falla mecánica | I501: =CHOOSE(RANDBETWEEN(1,10),"Baja","Baja","Baja","Media","Media","Media","Media","Alta","Alta","Alta") -> Media | J501: =CHOOSE(RANDBETWEEN(1,10),"Atendida","Atendida","Atendida","En curso","En curso","Pendiente","Pendiente","Atendida","Atendida","Atendida") -> Atendida | K501: =IF(J501="Atendida",B501+RANDBETWEEN(0,2),"") -> 45635 | L501: =IF(J501="Atendida",RANDBETWEEN(1,24),"") -> 1 | M501: =IF(OR(G501="Escalera eléctrica",G501="Ascensor",G501="Puertas de andén"),"Mantenimiento",IF(G501="Sistema eléctrico","Infraestructura","Telecomunicaciones")) -> Telecomunicaciones

Sheet DATA SET
A1: id_incidencia | B1: fecha_reporte | C1: mes_reporte | D1: hora_reporte | E1: estacion | F1: linea | G1: tipo_equipo | H1: tipo_incidencia | I1: prioridad | J1: estado | K1: fecha_atencion | L1: tiempo_atencion_horas | M1: area_responsable
A2: 1 | B2: 45255 | C2: 2023-11 | D2: 0.077777778 | E2: Cabitos | F2: Línea 1 | G2: Ascensor | H2: Falla mecánica | I2: Baja | J2: En curso | M2: Mantenimiento
A3: 2 | B3: 45423 | C3: 2024-05 | D3: 0.18055556 | E3: Villa El Salvador | F3: Línea 1 | G3: Torniquete | H3: Mantenimiento preventivo | I3: Media | J3: Atendida | K3: 45424 | L3: 10 | M3: Telecomunicaciones
A4: 3 | B4: 44988 | C4: 2023-03 | D4: 0.74027778 | E4: Villa El Salvador | F4: Línea 1 | G4: Radio | H4: Daño en infraestructura | I4: Alta | J4: Atendida | K4: 44990 | L4: 4 | M4: Telecomunicaciones
A5: 4 | B5: 44954 | C5: 2023-01 | D5: 0.65486111 | E5: Villa El Salvador | F5: Línea 1 | G5: Escalera eléctrica | H5: Falla eléctrica | I5: Alta | J5: Atendida | K5: 44954 | L5: 13 | M5: Mantenimiento
A6: 5 | B6: 45092 | C6: 2023-06 | D6: 0.050694444 | E6: Angamos | F6: Línea 1 | G6: Radio | H6: Daño en infraestructura | I6: Alta | J6: Atendida | K6: 45094 | L6: 12 | M6: Telecomunicaciones
A7: 6 | B7: 45010 | C7: 2023-03 | D7: 0.32222222 | E7: Cabitos | F7: Línea 1 | G7: MET | H7: Falla mecánica | I7: Media | J7: Atendida | K7: 45011 | L7: 14 | M7: Telecomunicaciones
A8: 7 | B8: 45239 | C8: 2023-11 | D8: 0.0083333333 | E8: Bayóvar | F8: Línea 1 | G8: Radio | H8: Falla eléctrica | I8: Baja | J8: Atendida | K8: 45239 | L8: 5 | M8: Telecomunicaciones
A9: 8 | B9: 45182 | C9: 2023-09 | D9: 0.81527778 | E9: Villa El Salvador | F9: Línea 1 | G9: Radio | H9: Falla eléctrica | I9: Alta | J9: Atendida | K9: 45184 | L9: 23 | M9: Telecomunicaciones
A10: 9 | B10: 45293 | C10: 2024-01 | D10: 0.57916667 | E10: Villa El Salvador | F10: Línea 1 | G10: Radio | H10: Falla eléctrica | I10: Media | J10: Atendida | K10: 45294 | L10: 14 | M10: Telecomunicaciones
A11: 10 | B11: 45115 | C11: 2023-07 | D11: 0.55625 | E11: Cabitos | F11: Línea 1 | G11: Ascensor | H11: Falla eléctrica | I11: Baja | J11: Atendida | K11: 45117 | L11: 5 | M11: Mantenimiento
A12: 11 | B12: 45065 | C12: 2023-05 | D12: 0.73958333 | E12: Angamos | F12: Línea 1 | G12: Radio | H12: Falla mecánica | I12: Alta | J12: Atendida | K12: 45065 | L12: 4 | M12: Telecomunicaciones
A13: 12 | B13: 45037 | C13: 2023-04 | D13: 0.29513889 | E13: San Carlos | F13: Línea 1 | G13: Ascensor | H13: Falla eléctrica | I13: Alta | J13: Atendida | K13: 45039 | L13: 2 | M13: Mantenimiento
A14: 13 | B14: 45212 | C14: 2023-10 | D14: 0.25208333 | E14: San Borja Sur | F14: Línea 1 | G14: Torniquete | H14: Falla eléctrica | I14: Media | J14: Pendiente | M14: Telecomunicaciones
A15: 14 | B15: 45384 | C15: 2024-04 | D15: 0.98819444 | E15: Cabitos | F15: Línea 1 | G15: Escalera eléctrica | H15: Daño en infraestructura | I15: Baja | J15: Atendida | K15: 45385 | L15: 19 | M15: Mantenimiento
A16: 15 | B16: 45458 | C16: 2024-06 | D16: 0.24375 | E16: Atocongo | F16: Línea 1 | G16: Torniquete | H16: Falla mecánica | I16: Media | J16: Atendida | K16: 45459 | L16: 23 | M16: Telecomunicaciones
A17: 16 | B17: 45643 | C17: 2024-12 | D17: 0.20972222 | E17: Angamos | F17: Línea 1 | G17: Escalera eléctrica | H17: Daño en infraestructura | I17: Baja | J17: En curso | M17: Mantenimiento
A18: 17 | B18: 44930 | C18: 2023-01 | D18: 0.89722222 | E18: Gamarra | F18: Línea 1 | G18: Radio | H18: Daño en infraestructura | I18: Alta | J18: Atendida | K18: 44930 | L18: 1 | M18: Telecomunicaciones
A19: 18 | B19: 45288 | C19: 2023-12 | D19: 0.25208333 | E19: Bayóvar | F19: Línea 1 | G19: Ascensor | H19: Daño en infraestructura | I19: Baja | J19: En curso | M19: Mantenimiento
A20: 19 | B20: 45426 | C20: 2024-05 | D20: 0.14791667 | E20: Santa Rosa | F20: Línea 1 | G20: TVM | H20: Falla eléctrica | I20: Baja | J20: Atendida | K20: 45427 | L20: 11 | M20: Telecomunicaciones
A21: 20 | B21: 45444 | C21: 2024-06 | D21: 0.62083333 | E21: La Cultura | F21: Línea 1 | G21: MET | H21: Falla mecánica | I21: Alta | J21: Pendiente | M21: Telecomunicaciones
A22: 21 | B22: 45133 | C22: 2023-07 | D22: 0.89583333 | E22: Ayacucho | F22: Línea 1 | G22: MET | H22: Daño en infraestructura | I22: Baja | J22: Atendida | K22: 45135 | L22: 9 | M22: Telecomunicaciones
A23: 22 | B23: 45214 | C23: 2023-10 | D23: 0.35208333 | E23: San Borja Sur | F23: Línea 1 | G23: TVM | H23: Falla eléctrica | I23: Alta | J23: Pendiente | M23: Telecomunicaciones
A24: 23 | B24: 44973 | C24: 2023-02 | D24: 0.38888889 | E24: La Cultura | F24: Línea 1 | G24: Ascensor | H24: Falla mecánica | I24: Media | J24: Atendida | K24: 44975 | L24: 19 | M24: Mantenimiento
A25: 24 | B25: 45055 | C25: 2023-05 | D25: 0.49861111 | E25: Bayóvar | F25: Línea 1 | G25: Escalera eléctrica | H25: Falla eléctrica | I25: Media | J25: Atendida | K25: 45057 | L25: 12 | M25: Mantenimiento
A26: 25 | B26: 45369 | C26: 2024-03 | D26: 0.021527778 | E26: San Borja Sur | F26: Línea 1 | G26: Ascensor | H26: Daño en infraestructura | I26: Baja | J26: Atendida | K26: 45371 | L26: 19 | M26: Mantenimiento
A27: 26 | B27: 45314 | C27: 2024-01 | D27: 0.0055555556 | E27: San Borja Sur | F27: Línea 1 | G27: MET | H27: Falla eléctrica | I27: Alta | J27: Atendida | K27: 45316 | L27: 4 | M27: Telecomunicaciones
A28: 27 | B28: 44955 | C28: 2023-01 | D28: 0.58055556 | E28: San Borja Sur | F28: Línea 1 | G28: MET | H28: Mantenimiento preventivo | I28: Media | J28: En curso | M28: Telecomunicaciones
A29: 28 | B29: 45190 | C29: 2023-09 | D29: 0.98333333 | E29: Ayacucho | F29: Línea 1 | G29: Torniquete | H29: Falla eléctrica | I29: Alta | J29: Atendida | K29: 45192 | L29: 2 | M29: Telecomunicaciones
A30: 29 | B30: 45424 | C30: 2024-05 | D30: 0.31111111 | E30: Bayóvar | F30: Línea 1 | G30: Torniquete | H30: Falla mecánica | I30: Baja | J30: En curso | M30: Telecomunicaciones
A31: 30 | B31: 45638 | C31: 2024-12 | D31: 0.24305556 | E31: Ayacucho | F31: Línea 1 | G31: Torniquete | H31: Mantenimiento preventivo | I31: Baja | J31: Atendida | K31: 45639 | L31: 23 | M31: Telecomunicaciones
A32: 31 | B32: 44994 | C32: 2023-03 | D32: 0.43333333 | E32: San Carlos | F32: Línea 1 | G32: Radio | H32: Daño en infraestructura | I32: Media | J32: Atendida | K32: 44996 | L32: 22 | M32: Telecomunicaciones
A33: 32 | B33: 44963 | C33: 2023-02 | D33: 0.85694444 | E33: Villa El Salvador | F33: Línea 1 | G33: TVM | H33: Daño en infraestructura | I33: Baja | J33: Pendiente | M33: Telecomunicaciones
A34: 33 | B34: 45054 | C34: 2023-05 | D34: 0.54652778 | E34: Gamarra | F34: Línea 1 | G34: MET | H34: Falla eléctrica | I34: Alta | J34: En curso | M34: Telecomunicaciones
A35: 34 | B35: 45344 | C35: 2024-02 | D35: 0.13680556 | E35: Bayóvar | F35: Línea 1 | G35: Escalera eléctrica | H35: Mantenimiento preventivo | I35: Baja | J35: Atendida | K35: 45345 | L35: 20 | M35: Mantenimiento
A36: 35 | B36: 45509 | C36: 2024-08 | D36: 0.56041667 | E36: Villa El Salvador | F36: Línea 1 | G36: Escalera eléctrica | H36: Daño en infraestructura | I36: Alta | J36: Pendiente | M36: Mantenimiento
A37: 36 | B37: 44986 | C37: 2023-03 | D37: 0.79791667 | E37: Santa Rosa | F37: Línea 1 | G37: Torniquete | H37: Daño en infraestructura | I37: Baja | J37: En curso | M37: Telecomunicaciones
A38: 37 | B38: 45513 | C38: 2024-08 | D38: 0.82847222 | E38: Santa Rosa | F38: Línea 1 | G38: MET | H38: Mantenimiento preventivo | I38: Alta | J38: Atendida | K38: 45513 | L38: 9 | M38: Telecomunicaciones
A39: 38 | B39: 44980 | C39: 2023-02 | D39: 0.67222222 | E39: Bayóvar | F39: Línea 1 | G39: TVM | H39: Falla mecánica | I39: Media | J39: En curso | M39: Telecomunicaciones
A40: 39 | B40: 45391 | C40: 2024-04 | D40: 0.050694444 | E40: Bayóvar | F40: Línea 1 | G40: TVM | H40: Falla eléctrica | I40: Alta | J40: Atendida | K40: 45393 | L40: 18 | M40: Telecomunicaciones
...

Sheet lista
A1: Angamos | B1: Escalera eléctrica | C1: Falla mecánica
A2: Atocongo | B2: Ascensor | C2: Falla eléctrica
A3: Bayóvar | B3: Torniquete | C3: Daño en infraestructura
A4: La Cultura | B4: TVM | C4: Mantenimiento preventivo
A5: San Borja Sur | B5: MET
A6: Villa El Salvador | B6: Radio
A7: Ayacucho
A8: Pumacahua
A9: Cabitos
A10: Gamarra
A11: San Carlos
A12: Santa Rosa
